Workbook

Sheet Project Guide
A1: HR ANALYTICS PROJECT – Employee Attrition & Retention (Excel + Power BI)
A3: OBJECTIVE
A4: Find out how many employees leave, from which departments, when, and why – then recommend actions to improve retention.
A6: FILES / SHEETS
A7: HR_Data – 560 synthetic employee records (practice data, not real people). Columns: EmployeeID, Department, JobRole, Gender, Age, HireDate, ExitDate, Status, Salary, PerformanceRating, SatisfactionScore, Overtime, ExitReason. TenureYears, ExitYear, AgeGroup are formulas.
A8: Analysis – Finished Excel analysis built with formulas (COUNTIFS, AVERAGEIFS) + 2 charts. Compare your own work against this.
A10: PART A – EXCEL TASKS (do these yourself first)
A11: 1. Clean: check blanks, duplicates (Remove Duplicates on EmployeeID), data types for dates.
A12: 2. Add calculated columns: Tenure, Exit Year, Age Group, Salary Band (use IF / IFS).
A13: 3. Build a PivotTable: Department vs Status (Active/Left) → % of Row Total = attrition %.
A14: 4. PivotTable: Exit Year × Department (leavers trend) + a PivotChart.
A15: 5. Drivers: attrition by Overtime, Satisfaction Score, Age Group, Salary Band.
... A45: Data is randomly generated for practice. Leavers before 2021 are not shown in the yearly tables. 2026 figures are year-to-date (as of the date in Analysis!B2), so the 2026 attrition rate is partial.

Sheet Analysis
A1: HR Analytics – Attrition & Retention Analysis
A2: As-of date (input) | B2: 46322
A3: KPI | B3: Value
A4: Total Employees ever | B4: =COUNTA(HR_Data!$A$2:$A$561) -> 560
A5: Active Headcount | B5: =COUNTIFS(HR_Data!$H$2:$H$561,"Active") -> 420
A6: Leavers | B6: =COUNTIFS(HR_Data!$H$2:$H$561,"Left") -> 140
A7: Overall Attrition % | B7: =B6/B4 -> 0.25
A8: Overall Retention % | B8: =1-B7 -> 0.75
A9: Avg Tenure of Leavers (yrs) | B9: =AVERAGEIFS(HR_Data!$N$2:$N$561,HR_Data!$H$2:$H$561,"Left") -> 2.4771429
A11: 1. Department-wise Attrition & Retention
A12: Department | B12: Total Employees | C12: Active | D12: Leavers | E12: Attrition % | F12: Retention % | G12: Avg Salary | H12: Avg Satisfaction | I12: Overtime %
A13: Sales | B13: =COUNTIFS(HR_Data!$B$2:$B$561,A13) -> 110 | C13: =COUNTIFS(HR_Data!$B$2:$B$561,A13,HR_Data!$H$2:$H$561,"Active") -> 70 | D13: =COUNTIFS(HR_Data!$B$2:$B$561,A13,HR_Data!$H$2:$H$561,"Left") -> 40 | E13: =IFERROR(D13/B13,0) -> 0.36363636 | F13: =1-E13 -> 0.63636364 | G13: =AVERAGEIFS(HR_Data!$I$2:$I$561,HR_Data!$B$2:$B$561,A13) -> 61002.727 | H13: =AVERAGEIFS(HR_Data!$K$2:$K$561,HR_Data!$B$2:$B$561,A13) -> 3.1545455 | I13: =COUNTIFS(HR_Data!$B$2:$B$561,A13,HR_Data!$L$2:$L$561,"Yes")/B13 -> 0.45454545
A14: Customer Support | B14: =COUNTIFS(HR_Data!$B$2:$B$561,A14) -> 100 | C14: =COUNTIFS(HR_Data!$B$2:$B$561,A14,HR_Data!$H$2:$H$561,"Active") -> 77 | D14: =COUNTIFS(HR_Data!$B$2:$B$561,A14,HR_Data!$H$2:$H$561,"Left") -> 23 | E14: =IFERROR(D14/B14,0) -> 0.23 | F14: =1-E14 -> 0.77 | G14: =AVERAGEIFS(HR_Data!$I$2:$I$561,HR_Data!$B$2:$B$561,A14) -> 50891 | H14: =AVERAGEIFS(HR_Data!$K$2:$K$561,HR_Data!$B$2:$B$561,A14) -> 3.29 | I14: =COUNTIFS(HR_Data!$B$2:$B$561,A14,HR_Data!$L$2:$L$561,"Yes")/B14 -> 0.3
A15: IT | B15: =COUNTIFS(HR_Data!$B$2:$B$561,A15) -> 90 | C15: =COUNTIFS(HR_Data!$B$2:$B$561,A15,HR_Data!$H$2:$H$561,"Active") -> 71 | D15: =COUNTIFS(HR_Data!$B$2:$B$561,A15,HR_Data!$H$2:$H$561,"Left") -> 19 | E15: =IFERROR(D15/B15,0) -> 0.21111111 | F15: =1-E15 -> 0.78888889 | G15: =AVERAGEIFS(HR_Data!$I$2:$I$561,HR_Data!$B$2:$B$561,A15) -> 107667.78 | H15: =AVERAGEIFS(HR_Data!$K$2:$K$561,HR_Data!$B$2:$B$561,A15) -> 3.3555556 | I15: =COUNTIFS(HR_Data!$B$2:$B$561,A15,HR_Data!$L$2:$L$561,"Yes")/B15 -> 0.3
A16: HR | B16: =COUNTIFS(HR_Data!$B$2:$B$561,A16) -> 35 | C16: =COUNTIFS(HR_Data!$B$2:$B$561,A16,HR_Data!$H$2:$H$561,"Active") -> 24 | D16: =COUNTIFS(HR_Data!$B$2:$B$561,A16,HR_Data!$H$2:$H$561,"Left") -> 11 | E16: =IFERROR(D16/B16,0) -> 0.31428571 | F16: =1-E16 -> 0.68571429 | G16: =AVERAGEIFS(HR_Data!$I$2:$I$561,HR_Data!$B$2:$B$561,A16) -> 71265.714 | H16: =AVERAGEIFS(HR_Data!$K$2:$K$561,HR_Data!$B$2:$B$561,A16) -> 3.1714286 | I16: =COUNTIFS(HR_Data!$B$2:$B$561,A16,HR_Data!$L$2:$L$561,"Yes")/B16 -> 0.51428571
A17: Finance | B17: =COUNTIFS(HR_Data!$B$2:$B$561,A17) -> 60 | C17: =COUNTIFS(HR_Data!$B$2:$B$561,A17,HR_Data!$H$2:$H$561,"Active") -> 53 | D17: =COUNTIFS(HR_Data!$B$2:$B$561,A17,HR_Data!$H$2:$H$561,"Left") -> 7 | E17: =IFERROR(D17/B17,0) -> 0.11666667 | F17: =1-E17 -> 0.88333333 | G17: =AVERAGEIFS(HR_Data!$I$2:$I$561,HR_Data!$B$2:$B$561,A17) -> 81165 | H17: =AVERAGEIFS(HR_Data!$K$2:$K$561,HR_Data!$B$2:$B$561,A17) -> 3.35 | I17: =COUNTIFS(HR_Data!$B$2:$B$561,A17,HR_Data!$L$2:$L$561,"Yes")/B17 -> 0.28333333
A18: Operations | B18: =COUNTIFS(HR_Data!$B$2:$B$561,A18) -> 110 | C18: =COUNTIFS(HR_Data!$B$2:$B$561,A18,HR_Data!$H$2:$H$561,"Active") -> 85 | D18: =COUNTIFS(HR_Data!$B$2:$B$561,A18,HR_Data!$H$2:$H$561,"Left") -> 25 | E18: =IFERROR(D18/B18,0) -> 0.22727273 | F18: =1-E18 -> 0.77272727 | G18: =AVERAGEIFS(HR_Data!$I$2:$I$561,HR_Data!$B$2:$B$561,A18) -> 54377.273 | H18: =AVERAGEIFS(HR_Data!$K$2:$K$561,HR_Data!$B$2:$B$561,A18) -> 3.3545455 | I18: =COUNTIFS(HR_Data!$B$2:$B$561,A18,HR_Data!$L$2:$L$561,"Yes")/B18 -> 0.29090909
A19: Marketing | B19: =COUNTIFS(HR_Data!$B$2:$B$561,A19) -> 55 | C19: =COUNTIFS(HR_Data!$B$2:$B$561,A19,HR_Data!$H$2:$H$561,"Active") -> 40 | D19: =COUNTIFS(HR_Data!$B$2:$B$561,A19,HR_Data!$H$2:$H$561,"Left") -> 15 | E19: =IFERROR(D19/B19,0) -> 0.27272727 | F19: =1-E19 -> 0.72727273 | G19: =AVERAGEIFS(HR_Data!$I$2:$I$561,HR_Data!$B$2:$B$561,A19) -> 72569.091 | H19: =AVERAGEIFS(HR_Data!$K$2:$K$561,HR_Data!$B$2:$B$561,A19) -> 3.3272727 | I19: =COUNTIFS(HR_Data!$B$2:$B$561,A19,HR_Data!$L$2:$L$561,"Yes")/B19 -> 0.27272727
A20: Total | B20: =SUM(B13:B19) -> 560 | C20: =SUM(C13:C19) -> 420 | D20: =SUM(D13:D19) -> 140 | E20: =D20/B20 -> 0.25 | F20: =1-E20 -> 0.75
A23: 2. Leavers by Department & Year (Exit Year Trend)
A24: Department | B24: 2021 | C24: 2022 | D24: 2023 | E24: 2024 | F24: 2025 | G24: 2026 | H24: Total
A25: Sales | B25: =COUNTIFS(HR_Data!$B$2:$B$561,$A25,HR_Data!$O$2:$O$561,B$24) -> 2 | C25: =COUNTIFS(HR_Data!$B$2:$B$561,$A25,HR_Data!$O$2:$O$561,C$24) -> 1 | D25: =COUNTIFS(HR_Data!$B$2:$B$561,$A25,HR_Data!$O$2:$O$561,D$24) -> 3 | E25: =COUNTIFS(HR_Data!$B$2:$B$561,$A25,HR_Data!$O$2:$O$561,E$24) -> 9 | F25: =COUNTIFS(HR_Data!$B$2:$B$561,$A25,HR_Data!$O$2:$O$561,F$24) -> 16 | G25: =COUNTIFS(HR_Data!$B$2:$B$561,$A25,HR_Data!$O$2:$O$561,G$24) -> 9 | H25: =SUM(B25:G25) -> 40
A26: Customer Support | B26: =COUNTIFS(HR_Data!$B$2:$B$561,$A26,HR_Data!$O$2:$O$561,B$24) -> 1 | C26: =COUNTIFS(HR_Data!$B$2:$B$561,$A26,HR_Data!$O$2:$O$561,C$24) -> 1 | D26: =COUNTIFS(HR_Data!$B$2:$B$561,$A26,HR_Data!$O$2:$O$561,D$24) -> 0 | E26: =COUNTIFS(HR_Data!$B$2:$B$561,$A26,HR_Data!$O$2:$O$561,E$24) -> 5 | F26: =COUNTIFS(HR_Data!$B$2:$B$561,$A26,HR_Data!$O$2:$O$561,F$24) -> 6 | G26: =COUNTIFS(HR_Data!$B$2:$B$561,$A26,HR_Data!$O$2:$O$561,G$24) -> 9 | H26: =SUM(B26:G26) -> 22
A27: IT | B27: =COUNTIFS(HR_Data!$B$2:$B$561,$A27,HR_Data!$O$2:$O$561,B$24) -> 0 | C27: =COUNTIFS(HR_Data!$B$2:$B$561,$A27,HR_Data!$O$2:$O$561,C$24) -> 1 | D27: =COUNTIFS(HR_Data!$B$2:$B$561,$A27,HR_Data!$O$2:$O$561,D$24) -> 1 | E27: =COUNTIFS(HR_Data!$B$2:$B$561,$A27,HR_Data!$O$2:$O$561,E$24) -> 2 | F27: =COUNTIFS(HR_Data!$B$2:$B$561,$A27,HR_Data!$O$2:$O$561,F$24) -> 0 | G27: =COUNTIFS(HR_Data!$B$2:$B$561,$A27,HR_Data!$O$2:$O$561,G$24) -> 14 | H27: =SUM(B27:G27) -> 18
A28: HR | B28: =COUNTIFS(HR_Data!$B$2:$B$561,$A28,HR_Data!$O$2:$O$561,B$24) -> 0 | C28: =COUNTIFS(HR_Data!$B$2:$B$561,$A28,HR_Data!$O$2:$O$561,C$24) -> 1 | D28: =COUNTIFS(HR_Data!$B$2:$B$561,$A28,HR_Data!$O$2:$O$561,D$24) -> 0 | E28: =COUNTIFS(HR_Data!$B$2:$B$561,$A28,HR_Data!$O$2:$O$561,E$24) -> 1 | F28: =COUNTIFS(HR_Data!$B$2:$B$561,$A28,HR_Data!$O$2:$O$561,F$24) -> 4 | G28: =COUNTIFS(HR_Data!$B$2:$B$561,$A28,HR_Data!$O$2:$O$561,G$24) -> 4 | H28: =SUM(B28:G28) -> 10
A29: Finance | B29: =COUNTIFS(HR_Data!$B$2:$B$561,$A29,HR_Data!$O$2:$O$561,B$24) -> 0 | C29: =COUNTIFS(HR_Data!$B$2:$B$561,$A29,HR_Data!$O$2:$O$561,C$24) -> 0 | D29: =COUNTIFS(HR_Data!$B$2:$B$561,$A29,HR_Data!$O$2:$O$561,D$24) -> 1 | E29: =COUNTIFS(HR_Data!$B$2:$B$561,$A29,HR_Data!$O$2:$O$561,E$24) -> 2 | F29: =COUNTIFS(HR_Data!$B$2:$B$561,$A29,HR_Data!$O$2:$O$561,F$24) -> 1 | G29: =COUNTIFS(HR_Data!$B$2:$B$561,$A29,HR_Data!$O$2:$O$561,G$24) -> 3 | H29: =SUM(B29:G29) -> 7
A30: Operations | B30: =COUNTIFS(HR_Data!$B$2:$B$561,$A30,HR_Data!$O$2:$O$561,B$24) -> 1 | C30: =COUNTIFS(HR_Data!$B$2:$B$561,$A30,HR_Data!$O$2:$O$561,C$24) -> 2 | D30: =COUNTIFS(HR_Data!$B$2:$B$561,$A30,HR_Data!$O$2:$O$561,D$24) -> 2 | E30: =COUNTIFS(HR_Data!$B$2:$B$561,$A30,HR_Data!$O$2:$O$561,E$24) -> 3 | F30: =COUNTIFS(HR_Data!$B$2:$B$561,$A30,HR_Data!$O$2:$O$561,F$24) -> 2 | G30: =COUNTIFS(HR_Data!$B$2:$B$561,$A30,HR_Data!$O$2:$O$561,G$24) -> 13 | H30: =SUM(B30:G30) -> 23
A31: Marketing | B31: =COUNTIFS(HR_Data!$B$2:$B$561,$A31,HR_Data!$O$2:$O$561,B$24) -> 1 | C31: =COUNTIFS(HR_Data!$B$2:$B$561,$A31,HR_Data!$O$2:$O$561,C$24) -> 1 | D31: =COUNTIFS(HR_Data!$B$2:$B$561,$A31,HR_Data!$O$2:$O$561,D$24) -> 3 | E31: =COUNTIFS(HR_Data!$B$2:$B$561,$A31,HR_Data!$O$2:$O$561,E$24) -> 5 | F31: =COUNTIFS(HR_Data!$B$2:$B$561,$A31,HR_Data!$O$2:$O$561,F$24) -> 2 | G31: =COUNTIFS(HR_Data!$B$2:$B$561,$A31,HR_Data!$O$2:$O$561,G$24) -> 3 | H31: =SUM(B31:G31) -> 15
A32: Total | B32: =SUM(B25:B31) -> 5 | C32: =SUM(C25:C31) -> 7 | D32: =SUM(D25:D31) -> 10 | E32: =SUM(E25:E31) -> 27 | F32: =SUM(F25:F31) -> 31 | G32: =SUM(G25:G31) -> 55 | H32: =SUM(H25:H31) -> 135
A35: 3. Annual Attrition Rate % by Department (Leavers ÷ Headcount at 1-Jan; 2026 is year-to-date)
A36: Department | B36: 2021 | C36: 2022 | D36: 2023 | E36: 2024 | F36: 2025 | G36: 2026
A37: Sales | B37: =IFERROR(B25/(COUNTIFS(HR_Data!$B$2:$B$561,$A37,HR_Data!$F$2:$F$561,"<"&DATE(B$36,1,1))-COUNTIFS(HR_Data!$B$2:$B$561,$A37,HR_Data!$G$2:$G$561,"<"&DATE(B$36,1,1))),0) -> 0.055555556 | C37: =IFERROR(C25/(COUNTIFS(HR_Data!$B$2:$B$561,$A37,HR_Data!$F$2:$F$561,"<"&DATE(C$36,1,1))-COUNTIFS(HR_Data!$B$2:$B$561,$A37,HR_Data!$G$2:$G$561,"<"&DATE(C$36,1,1))),0) -> 0.022222222 | D37: =IFERROR(D25/(COUNTIFS(HR_Data!$B$2:$B$561,$A37,HR_Data!$F$2:$F$561,"<"&DATE(D$36,1,1))-COUNTIFS(HR_Data!$B$2:$B$561,$A37,HR_Data!$G$2:$G$561,"<"&DATE(D$36,1,1))),0) -> 0.051724138 | E37: =IFERROR(E25/(COUNTIFS(HR_Data!$B$2:$B$561,$A37,HR_Data!$F$2:$F$561,"<"&DATE(E$36,1,1))-COUNTIFS(HR_Data!$B$2:$B$561,$A37,HR_Data!$G$2:$G$561,"<"&DATE(E$36,1,1))),0) -> 0.13043478 | F37: =IFERROR(F25/(COUNTIFS(HR_Data!$B$2:$B$561,$A37,HR_Data!$F$2:$F$561,"<"&DATE(F$36,1,1))-COUNTIFS(HR_Data!$B$2:$B$561,$A37,HR_Data!$G$2:$G$561,"<"&DATE(F$36,1,1))),0) -> 0.21917808 | G37: =IFERROR(G25/(COUNTIFS(HR_Data!$B$2:$B$561,$A37,HR_Data!$F$2:$F$561,"<"&DATE(G$36,1,1))-COUNTIFS(HR_Data!$B$2:$B$561,$A37,HR_Data!$G$2:$G$561,"<"&DATE(G$36,1,1))),0) -> 0.12
A38: Customer Support | B38: =IFERROR(B26/(COUNTIFS(HR_Data!$B$2:$B$561,$A38,HR_Data!$F$2:$F$561,"<"&DATE(B$36,1,1))-COUNTIFS(HR_Data!$B$2:$B$561,$A38,HR_Data!$G$2:$G$561,"<"&DATE(B$36,1,1))),0) -> 0.032258065 | C38: =IFERROR(C26/(COUNTIFS(HR_Data!$B$2:$B$561,$A38,HR_Data!$F$2:$F$561,"<"&DATE(C$36,1,1))-COUNTIFS(HR_Data!$B$2:$B$561,$A38,HR_Data!$G$2:$G$561,"<"&DATE(C$36,1,1))),0) -> 0.023809524 | D38: =IFERROR(D26/(COUNTIFS(HR_Data!$B$2:$B$561,$A38,HR_Data!$F$2:$F$561,"<"&DATE(D$36,1,1))-COUNTIFS(HR_Data!$B$2:$B$561,$A38,HR_Data!$G$2:$G$561,"<"&DATE(D$36,1,1))),0) -> 0 | E38: =IFERROR(E26/(COUNTIFS(HR_Data!$B$2:$B$561,$A38,HR_Data!$F$2:$F$561,"<"&DATE(E$36,1,1))-COUNTIFS(HR_Data!$B$2:$B$561,$A38,HR_Data!$G$2:$G$561,"<"&DATE(E$36,1,1))),0) -> 0.072463768 | F38: =IFERROR(F26/(COUNTIFS(HR_Data!$B$2:$B$561,$A38,HR_Data!$F$2:$F$561,"<"&DATE(F$36,1,1))-COUNTIFS(HR_Data!$B$2:$B$561,$A38,HR_Data!$G$2:$G$561,"<"&DATE(F$36,1,1))),0) -> 0.08 | G38: =IFERROR(G26/(COUNTIFS(HR_Data!$B$2:$B$561,$A38,HR_Data!$F$2:$F$561,"<"&DATE(G$36,1,1))-COUNTIFS(HR_Data!$B$2:$B$561,$A38,HR_Data!$G$2:$G$561,"<"&DATE(G$36,1,1))),0) -> 0.11538462
A39: IT | B39: =IFERROR(B27/(COUNTIFS(HR_Data!$B$2:$B$561,$A39,HR_Data!$F$2:$F$561,"<"&DATE(B$36,1,1))-COUNTIFS(HR_Data!$B$2:$B$561,$A39,HR_Data!$G$2:$G$561,"<"&DATE(B$36,1,1))),0) -> 0 | C39: =IFERROR(C27/(COUNTIFS(HR_Data!$B$2:$B$561,$A39,HR_Data!$F$2:$F$561,"<"&DATE(C$36,1,1))-COUNTIFS(HR_Data!$B$2:$B$561,$A39,HR_Data!$G$2:$G$561,"<"&DATE(C$36,1,1))),0) -> 0.025 | D39: =IFERROR(D27/(COUNTIFS(HR_Data!$B$2:$B$561,$A39,HR_Data!$F$2:$F$561,"<"&DATE(D$36,1,1))-COUNTIFS(HR_Data!$B$2:$B$561,$A39,HR_Data!$G$2:$G$561,"<"&DATE(D$36,1,1))),0) -> 0.02173913 | E39: =IFERROR(E27/(COUNTIFS(HR_Data!$B$2:$B$561,$A39,HR_Data!$F$2:$F$561,"<"&DATE(E$36,1,1))-COUNTIFS(HR_Data!$B$2:$B$561,$A39,HR_Data!$G$2:$G$561,"<"&DATE(E$36,1,1))),0) -> 0.039215686 | F39: =IFERROR(F27/(COUNTIFS(HR_Data!$B$2:$B$561,$A39,HR_Data!$F$2:$F$561,"<"&DATE(F$36,1,1))-COUNTIFS(HR_Data!$B$2:$B$561,$A39,HR_Data!$G$2:$G$561,"<"&DATE(F$36,1,1))),0) -> 0 | G39: =IFERROR(G27/(COUNTIFS(HR_Data!$B$2:$B$561,$A39,HR_Data!$F$2:$F$561,"<"&DATE(G$36,1,1))-COUNTIFS(HR_Data!$B$2:$B$561,$A39,HR_Data!$G$2:$G$561,"<"&DATE(G$36,1,1))),0) -> 0.18666667
A40: HR | B40: =IFERROR(B28/(COUNTIFS(HR_Data!$B$2:$B$561,$A40,HR_Data!$F$2:$F$561,"<"&DATE(B$36,1,1))-COUNTIFS(HR_Data!$B$2:$B$561,$A40,HR_Data!$G$2:$G$561,"<"&DATE(B$36,1,1))),0) -> 0 | C40: =IFERROR(C28/(COUNTIFS(HR_Data!$B$2:$B$561,$A40,HR_Data!$F$2:$F$561,"<"&DATE(C$36,1,1))-COUNTIFS(HR_Data!$B$2:$B$561,$A40,HR_Data!$G$2:$G$561,"<"&DATE(C$36,1,1))),0) -> 0.0625 | D40: =IFERROR(D28/(COUNTIFS(HR_Data!$B$2:$B$561,$A40,HR_Data!$F$2:$F$561,"<"&DATE(D$36,1,1))-COUNTIFS(HR_Data!$B$2:$B$561,$A40,HR_Data!$G$2:$G$561,"<"&DATE(D$36,1,1))),0) -> 0 | E40: =IFERROR(E28/(COUNTIFS(HR_Data!$B$2:$B$561,$A40,HR_Data!$F$2:$F$561,"<"&DATE(E$36,1,1))-COUNTIFS(HR_Data!$B$2:$B$561,$A40,HR_Data!$G$2:$G$561,"<"&DATE(E$36,1,1))),0) -> 0.055555556 | F40: =IFERROR(F28/(COUNTIFS(HR_Data!$B$2:$B$561,$A40,HR_Data!$F$2:$F$561,"<"&DATE(F$36,1,1))-COUNTIFS(HR_Data!$B$2:$B$561,$A40,HR_Data!$G$2:$G$561,"<"&DATE(F$36,1,1))),0) -> 0.19047619 | G40: =IFERROR(G28/(COUNTIFS(HR_Data!$B$2:$B$561,$A40,HR_Data!$F$2:$F$561,"<"&DATE(G$36,1,1))-COUNTIFS(HR_Data!$B$2:$B$561,$A40,HR_Data!$G$2:$G$561,"<"&DATE(G$36,1,1))),0) -> 0.16666667
A41: Finance | B41: =IFERROR(B29/(COUNTIFS(HR_Data!$B$2:$B$561,$A41,HR_Data!$F$2:$F$561,"<"&DATE(B$36,1,1))-COUNTIFS(HR_Data!$B$2:$B$561,$A41,HR_Data!$G$2:$G$561,"<"&DATE(B$36,1,1))),0) -> 0 | C41: =IFERROR(C29/(COUNTIFS(HR_Data!$B$2:$B$561,$A41,HR_Data!$F$2:$F$561,"<"&DATE(C$36,1,1))-COUNTIFS(HR_Data!$B$2:$B$561,$A41,HR_Data!$G$2:$G$561,"<"&DATE(C$36,1,1))),0) -> 0 | D41: =IFERROR(D29/(COUNTIFS(HR_Data!$B$2:$B$561,$A41,HR_Data!$F$2:$F$561,"<"&DATE(D$36,1,1))-COUNTIFS(HR_Data!$B$2:$B$561,$A41,HR_Data!$G$2:$G$561,"<"&DATE(D$36,1,1))),0) -> 0.03125 | E41: =IFERROR(E29/(COUNTIFS(HR_Data!$B$2:$B$561,$A41,HR_Data!$F$2:$F$561,"<"&DATE(E$36,1,1))-COUNTIFS(HR_Data!$B$2:$B$561,$A41,HR_Data!$G$2:$G$561,"<"&DATE(E$36,1,1))),0) -> 0.051282051 | F41: =IFERROR(F29/(COUNTIFS(HR_Data!$B$2:$B$561,$A41,HR_Data!$F$2:$F$561,"<"&DATE(F$36,1,1))-COUNTIFS(HR_Data!$B$2:$B$561,$A41,HR_Data!$G$2:$G$561,"<"&DATE(F$36,1,1))),0) -> 0.025 | G41: =IFERROR(G29/(COUNTIFS(HR_Data!$B$2:$B$561,$A41,HR_Data!$F$2:$F$561,"<"&DATE(G$36,1,1))-COUNTIFS(HR_Data!$B$2:$B$561,$A41,HR_Data!$G$2:$G$561,"<"&DATE(G$36,1,1))),0) -> 0.06
A42: Operations | B42: =IFERROR(B30/(COUNTIFS(HR_Data!$B$2:$B$561,$A42,HR_Data!$F$2:$F$561,"<"&DATE(B$36,1,1))-COUNTIFS(HR_Data!$B$2:$B$561,$A42,HR_Data!$G$2:$G$561,"<"&DATE(B$36,1,1))),0) -> 0.027027027 | C42: =IFERROR(C30/(COUNTIFS(HR_Data!$B$2:$B$561,$A42,HR_Data!$F$2:$F$561,"<"&DATE(C$36,1,1))-COUNTIFS(HR_Data!$B$2:$B$561,$A42,HR_Data!$G$2:$G$561,"<"&DATE(C$36,1,1))),0) -> 0.042553191 | D42: =IFERROR(D30/(COUNTIFS(HR_Data!$B$2:$B$561,$A42,HR_Data!$F$2:$F$561,"<"&DATE(D$36,1,1))-COUNTIFS(HR_Data!$B$2:$B$561,$A42,HR_Data!$G$2:$G$561,"<"&DATE(D$36,1,1))),0) -> 0.037037037 | E42: =IFERROR(E30/(COUNTIFS(HR_Data!$B$2:$B$561,$A42,HR_Data!$F$2:$F$561,"<"&DATE(E$36,1,1))-COUNTIFS(HR_Data!$B$2:$B$561,$A42,HR_Data!$G$2:$G$561,"<"&DATE(E$36,1,1))),0) -> 0.041666667 | F42: =IFERROR(F30/(COUNTIFS(HR_Data!$B$2:$B$561,$A42,HR_Data!$F$2:$F$561,"<"&DATE(F$36,1,1))-COUNTIFS(HR_Data!$B$2:$B$561,$A42,HR_Data!$G$2:$G$561,"<"&DATE(F$36,1,1))),0) -> 0.024691358 | G42: =IFERROR(G30/(COUNTIFS(HR_Data!$B$2:$B$561,$A42,HR_Data!$F$2:$F$561,"<"&DATE(G$36,1,1))-COUNTIFS(HR_Data!$B$2:$B$561,$A42,HR_Data!$G$2:$G$561,"<"&DATE(G$36,1,1))),0) -> 0.14606742
A43: Marketing | B43: =IFERROR(B31/(COUNTIFS(HR_Data!$B$2:$B$561,$A43,HR_Data!$F$2:$F$561,"<"&DATE(B$36,1,1))-COUNTIFS(HR_Data!$B$2:$B$561,$A43,HR_Data!$G$2:$G$561,"<"&DATE(B$36,1,1))),0) -> 0.0625 | C43: =IFERROR(C31/(COUNTIFS(HR_Data!$B$2:$B$561,$A43,HR_Data!$F$2:$F$561,"<"&DATE(C$36,1,1))-COUNTIFS(HR_Data!$B$2:$B$561,$A43,HR_Data!$G$2:$G$561,"<"&DATE(C$36,1,1))),0) -> 0.047619048 | D43: =IFERROR(D31/(COUNTIFS(HR_Data!$B$2:$B$561,$A43,HR_Data!$F$2:$F$561,"<"&DATE(D$36,1,1))-COUNTIFS(HR_Data!$B$2:$B$561,$A43,HR_Data!$G$2:$G$561,"<"&DATE(D$36,1,1))),0) -> 0.11111111 | E43: =IFERROR(E31/(COUNTIFS(HR_Data!$B$2:$B$561,$A43,HR_Data!$F$2:$F$561,"<"&DATE(E$36,1,1))-COUNTIFS(HR_Data!$B$2:$B$561,$A43,HR_Data!$G$2:$G$561,"<"&DATE(E$36,1,1))),0) -> 0.14705882 | F43: =IFERROR(F31/(COUNTIFS(HR_Data!$B$2:$B$561,$A43,HR_Data!$F$2:$F$561,"<"&DATE(F$36,1,1))-COUNTIFS(HR_Data!$B$2:$B$561,$A43,HR_Data!$G$2:$G$561,"<"&DATE(F$36,1,1))),0) -> 0.054054054 | G43: =IFERROR(G31/(COUNTIFS(HR_Data!$B$2:$B$561,$A43,HR_Data!$F$2:$F$561,"<"&DATE(G$36,1,1))-COUNTIFS(HR_Data!$B$2:$B$561,$A43,HR_Data!$G$2:$G$561,"<"&DATE(G$36,1,1))),0) -> 0.075
A46: 4. Attrition Drivers
A47: Overtime | B47: Employees | C47: Leavers | D47: Attrition %
...

Sheet HR_Data
A1: EmployeeID | B1: Department | C1: JobRole | D1: Gender | E1: Age | F1: HireDate | G1: ExitDate | H1: Status | I1: Salary | J1: PerformanceRating | K1: SatisfactionScore | L1: Overtime | M1: ExitReason | N1: TenureYears | O1: ExitYear | P1: AgeGroup
A2: E1204 | B2: Customer Support | C2: Support Agent | D2: Male | E2: 28 | F2: 45619 | H2: Active | I2: 31400 | J2: 1 | K2: 5 | L2: No | N2: =ROUND((IF(G2="",Analysis!$B$2,G2)-F2)/365.25,1) -> 1.9 | O2: =IF(G2="","",YEAR(G2)) | P2: =IF(E2<30,"<30",IF(E2<40,"30-39","40+")) -> <30
A3: E1188 | B3: Customer Support | C3: Support Agent | D3: Male | E3: 50 | F3: 45292 | H3: Active | I3: 35900 | J3: 1 | K3: 5 | L3: No | N3: =ROUND((IF(G3="",Analysis!$B$2,G3)-F3)/365.25,1) -> 2.8 | O3: =IF(G3="","",YEAR(G3)) | P3: =IF(E3<30,"<30",IF(E3<40,"30-39","40+")) -> 40+
A4: E1491 | B4: Operations | C4: Operations Associate | D4: Female | E4: 27 | F4: 44686 | H4: Active | I4: 38800 | J4: 1 | K4: 4 | L4: No | N4: =ROUND((IF(G4="",Analysis!$B$2,G4)-F4)/365.25,1) -> 4.5 | O4: =IF(G4="","",YEAR(G4)) | P4: =IF(E4<30,"<30",IF(E4<40,"30-39","40+")) -> <30
A5: E1085 | B5: Sales | C5: Sales Executive | D5: Female | E5: 41 | F5: 44904 | H5: Active | I5: 39400 | J5: 1 | K5: 5 | L5: Yes | N5: =ROUND((IF(G5="",Analysis!$B$2,G5)-F5)/365.25,1) -> 3.9 | O5: =IF(G5="","",YEAR(G5)) | P5: =IF(E5<30,"<30",IF(E5<40,"30-39","40+")) -> 40+
A6: E1451 | B6: Operations | C6: Operations Associate | D6: Male | E6: 38 | F6: 43180 | H6: Active | I6: 44000 | J6: 1 | K6: 5 | L6: Yes | N6: =ROUND((IF(G6="",Analysis!$B$2,G6)-F6)/365.25,1) -> 8.6 | O6: =IF(G6="","",YEAR(G6)) | P6: =IF(E6<30,"<30",IF(E6<40,"30-39","40+")) -> 30-39
A7: E1030 | B7: Sales | C7: Sales Executive | D7: Female | E7: 21 | F7: 45699 | H7: Active | I7: 48300 | J7: 1 | K7: 3 | L7: No | N7: =ROUND((IF(G7="",Analysis!$B$2,G7)-F7)/365.25,1) -> 1.7 | O7: =IF(G7="","",YEAR(G7)) | P7: =IF(E7<30,"<30",IF(E7<40,"30-39","40+")) -> <30
A8: E1426 | B8: Operations | C8: Supervisor | D8: Male | E8: 34 | F8: 44790 | G8: 46259 | H8: Left | I8: 50600 | J8: 1 | K8: 3 | L8: No | M8: Higher Studies | N8: =ROUND((IF(G8="",Analysis!$B$2,G8)-F8)/365.25,1) -> 4 | O8: =IF(G8="","",YEAR(G8)) -> 2026 | P8: =IF(E8<30,"<30",IF(E8<40,"30-39","40+")) -> 30-39
A9: E1371 | B9: Finance | C9: Accountant | D9: Female | E9: 39 | F9: 44831 | H9: Active | I9: 54700 | J9: 1 | K9: 3 | L9: No | N9: =ROUND((IF(G9="",Analysis!$B$2,G9)-F9)/365.25,1) -> 4.1 | O9: =IF(G9="","",YEAR(G9)) | P9: =IF(E9<30,"<30",IF(E9<40,"30-39","40+")) -> 30-39
A10: E1055 | B10: Sales | C10: Account Manager | D10: Male | E10: 29 | F10: 43771 | H10: Active | I10: 60100 | J10: 1 | K10: 2 | L10: No | N10: =ROUND((IF(G10="",Analysis!$B$2,G10)-F10)/365.25,1) -> 7 | O10: =IF(G10="","",YEAR(G10)) | P10: =IF(E10<30,"<30",IF(E10<40,"30-39","40+")) -> <30
A11: E1120 | B11: Customer Support | C11: Support Analyst | D11: Female | E11: 37 | F11: 46231 | G11: 46321 | H11: Left | I11: 61200 | J11: 1 | K11: 3 | L11: Yes | M11: Manager Issues | N11: =ROUND((IF(G11="",Analysis!$B$2,G11)-F11)/365.25,1) -> 0.2 | O11: =IF(G11="","",YEAR(G11)) -> 2026 | P11: =IF(E11<30,"<30",IF(E11<40,"30-39","40+")) -> 30-39
A12: E1360 | B12: Finance | C12: Accountant | D12: Male | E12: 31 | F12: 44753 | H12: Active | I12: 65400 | J12: 1 | K12: 4 | L12: No | N12: =ROUND((IF(G12="",Analysis!$B$2,G12)-F12)/365.25,1) -> 4.3 | O12: =IF(G12="","",YEAR(G12)) | P12: =IF(E12<30,"<30",IF(E12<40,"30-39","40+")) -> 30-39
A13: E1050 | B13: Sales | C13: Account Manager | D13: Female | E13: 39 | F13: 45100 | H13: Active | I13: 65900 | J13: 1 | K13: 3 | L13: Yes | N13: =ROUND((IF(G13="",Analysis!$B$2,G13)-F13)/365.25,1) -> 3.3 | O13: =IF(G13="","",YEAR(G13)) | P13: =IF(E13<30,"<30",IF(E13<40,"30-39","40+")) -> 30-39
A14: E1512 | B14: Marketing | C14: Content Specialist | D14: Female | E14: 42 | F14: 44966 | H14: Active | I14: 67600 | J14: 1 | K14: 3 | L14: No | N14: =ROUND((IF(G14="",Analysis!$B$2,G14)-F14)/365.25,1) -> 3.7 | O14: =IF(G14="","",YEAR(G14)) | P14: =IF(E14<30,"<30",IF(E14<40,"30-39","40+")) -> 40+
A15: E1409 | B15: Operations | C15: Logistics Coordinator | D15: Male | E15: 21 | F15: 44042 | G15: 44526 | H15: Left | I15: 67800 | J15: 1 | K15: 2 | L15: No | M15: Better Salary Elsewhere | N15: =ROUND((IF(G15="",Analysis!$B$2,G15)-F15)/365.25,1) -> 1.3 | O15: =IF(G15="","",YEAR(G15)) -> 2021 | P15: =IF(E15<30,"<30",IF(E15<40,"30-39","40+")) -> <30
A16: E1088 | B16: Sales | C16: Account Manager | D16: Female | E16: 32 | F16: 44918 | G16: 45775 | H16: Left | I16: 68600 | J16: 1 | K16: 3 | L16: Yes | M16: Relocation | N16: =ROUND((IF(G16="",Analysis!$B$2,G16)-F16)/365.25,1) -> 2.3 | O16: =IF(G16="","",YEAR(G16)) -> 2025 | P16: =IF(E16<30,"<30",IF(E16<40,"30-39","40+")) -> 30-39
A17: E1090 | B17: Sales | C17: Account Manager | D17: Female | E17: 28 | F17: 45713 | H17: Active | I17: 70800 | J17: 1 | K17: 3 | L17: Yes | N17: =ROUND((IF(G17="",Analysis!$B$2,G17)-F17)/365.25,1) -> 1.7 | O17: =IF(G17="","",YEAR(G17)) | P17: =IF(E17<30,"<30",IF(E17<40,"30-39","40+")) -> <30
A18: E1401 | B18: Operations | C18: Logistics Coordinator | D18: Male | E18: 31 | F18: 45024 | H18: Active | I18: 72900 | J18: 1 | K18: 5 | L18: No | N18: =ROUND((IF(G18="",Analysis!$B$2,G18)-F18)/365.25,1) -> 3.6 | O18: =IF(G18="","",YEAR(G18)) | P18: =IF(E18<30,"<30",IF(E18<40,"30-39","40+")) -> 30-39
A19: E1350 | B19: Finance | C19: Financial Analyst | D19: Male | E19: 21 | F19: 43306 | H19: Active | I19: 76400 | J19: 1 | K19: 2 | L19: Yes | N19: =ROUND((IF(G19="",Analysis!$B$2,G19)-F19)/365.25,1) -> 8.3 | O19: =IF(G19="","",YEAR(G19)) | P19: =IF(E19<30,"<30",IF(E19<40,"30-39","40+")) -> <30
A20: E1351 | B20: Finance | C20: Financial Analyst | D20: Male | E20: 39 | F20: 43490 | H20: Active | I20: 76400 | J20: 1 | K20: 5 | L20: No | N20: =ROUND((IF(G20="",Analysis!$B$2,G20)-F20)/365.25,1) -> 7.8 | O20: =IF(G20="","",YEAR(G20)) | P20: =IF(E20<30,"<30",IF(E20<40,"30-39","40+")) -> 30-39
A21: E1425 | B21: Operations | C21: Logistics Coordinator | D21: Female | E21: 34 | F21: 45892 | H21: Active | I21: 76600 | J21: 1 | K21: 4 | L21: No | N21: =ROUND((IF(G21="",Analysis!$B$2,G21)-F21)/365.25,1) -> 1.2 | O21: =IF(G21="","",YEAR(G21)) | P21: =IF(E21<30,"<30",IF(E21<40,"30-39","40+")) -> 30-39
A22: E1258 | B22: IT | C22: Software Engineer | D22: Female | E22: 34 | F22: 44963 | H22: Active | I22: 77400 | J22: 1 | K22: 3 | L22: No | N22: =ROUND((IF(G22="",Analysis!$B$2,G22)-F22)/365.25,1) -> 3.7 | O22: =IF(G22="","",YEAR(G22)) | P22: =IF(E22<30,"<30",IF(E22<40,"30-39","40+")) -> 30-39
A23: E1263 | B23: IT | C23: Data Analyst | D23: Other | E23: 29 | F23: 44859 | H23: Active | I23: 97500 | J23: 1 | K23: 4 | L23: No | N23: =ROUND((IF(G23="",Analysis!$B$2,G23)-F23)/365.25,1) -> 4 | O23: =IF(G23="","",YEAR(G23)) | P23: =IF(E23<30,"<30",IF(E23<40,"30-39","40+")) -> <30
A24: E1377 | B24: Finance | C24: Finance Manager | D24: Female | E24: 41 | F24: 44454 | H24: Active | I24: 105100 | J24: 1 | K24: 5 | L24: No | N24: =ROUND((IF(G24="",Analysis!$B$2,G24)-F24)/365.25,1) -> 5.1 | O24: =IF(G24="","",YEAR(G24)) | P24: =IF(E24<30,"<30",IF(E24<40,"30-39","40+")) -> 40+
A25: E1271 | B25: IT | C25: IT Support | D25: Female | E25: 44 | F25: 45506 | H25: Active | I25: 127300 | J25: 1 | K25: 3 | L25: Yes | N25: =ROUND((IF(G25="",Analysis!$B$2,G25)-F25)/365.25,1) -> 2.2 | O25: =IF(G25="","",YEAR(G25)) | P25: =IF(E25<30,"<30",IF(E25<40,"30-39","40+")) -> 40+
A26: E1276 | B26: IT | C26: DevOps Engineer | D26: Female | E26: 30 | F26: 46103 | G26: 46212 | H26: Left | I26: 135600 | J26: 1 | K26: 4 | L26: No | M26: Relocation | N26: =ROUND((IF(G26="",Analysis!$B$2,G26)-F26)/365.25,1) -> 0.3 | O26: =IF(G26="","",YEAR(G26)) -> 2026 | P26: =IF(E26<30,"<30",IF(E26<40,"30-39","40+")) -> 30-39
A27: E1186 | B27: Customer Support | C27: Support Agent | D27: Female | E27: 36 | F27: 43511 | H27: Active | I27: 30700 | J27: 2 | K27: 4 | L27: No | N27: =ROUND((IF(G27="",Analysis!$B$2,G27)-F27)/365.25,1) -> 7.7 | O27: =IF(G27="","",YEAR(G27)) | P27: =IF(E27<30,"<30",IF(E27<40,"30-39","40+")) -> 30-39
A28: E1144 | B28: Customer Support | C28: Support Agent | D28: Male | E28: 33 | F28: 43556 | H28: Active | I28: 35900 | J28: 2 | K28: 2 | L28: No | N28: =ROUND((IF(G28="",Analysis!$B$2,G28)-F28)/365.25,1) -> 7.6 | O28: =IF(G28="","",YEAR(G28)) | P28: =IF(E28<30,"<30",IF(E28<40,"30-39","40+")) -> 30-39
A29: E1418 | B29: Operations | C29: Operations Associate | D29: Female | E29: 22 | F29: 45032 | H29: Active | I29: 39200 | J29: 2 | K29: 3 | L29: No | N29: =ROUND((IF(G29="",Analysis!$B$2,G29)-F29)/365.25,1) -> 3.5 | O29: =IF(G29="","",YEAR(G29)) | P29: =IF(E29<30,"<30",IF(E29<40,"30-39","40+")) -> <30
A30: E1416 | B30: Operations | C30: Operations Associate | D30: Male | E30: 31 | F30: 46114 | H30: Active | I30: 40300 | J30: 2 | K30: 5 | L30: Yes | N30: =ROUND((IF(G30="",Analysis!$B$2,G30)-F30)/365.25,1) -> 0.6 | O30: =IF(G30="","",YEAR(G30)) | P30: =IF(E30<30,"<30",IF(E30<40,"30-39","40+")) -> 30-39
A31: E1042 | B31: Sales | C31: Sales Executive | D31: Male | E31: 35 | F31: 45856 | H31: Active | I31: 42100 | J31: 2 | K31: 4 | L31: Yes | N31: =ROUND((IF(G31="",Analysis!$B$2,G31)-F31)/365.25,1) -> 1.3 | O31: =IF(G31="","",YEAR(G31)) | P31: =IF(E31<30,"<30",IF(E31<40,"30-39","40+")) -> 30-39
A32: E1019 | B32: Sales | C32: Sales Executive | D32: Female | E32: 31 | F32: 45859 | G32: 46178 | H32: Left | I32: 42200 | J32: 2 | K32: 4 | L32: No | M32: Career Growth | N32: =ROUND((IF(G32="",Analysis!$B$2,G32)-F32)/365.25,1) -> 0.9 | O32: =IF(G32="","",YEAR(G32)) -> 2026 | P32: =IF(E32<30,"<30",IF(E32<40,"30-39","40+")) -> 30-39
A33: E1309 | B33: HR | C33: HR Executive | D33: Female | E33: 21 | F33: 45806 | G33: 45940 | H33: Left | I33: 43500 | J33: 2 | K33: 2 | L33: Yes | M33: Career Growth | N33: =ROUND((IF(G33="",Analysis!$B$2,G33)-F33)/365.25,1) -> 0.4 | O33: =IF(G33="","",YEAR(G33)) -> 2025 | P33: =IF(E33<30,"<30",IF(E33<40,"30-39","40+")) -> <30
A34: E1136 | B34: Customer Support | C34: Team Lead | D34: Male | E34: 28 | F34: 45812 | H34: Active | I34: 43900 | J34: 2 | K34: 4 | L34: No | N34: =ROUND((IF(G34="",Analysis!$B$2,G34)-F34)/365.25,1) -> 1.4 | O34: =IF(G34="","",YEAR(G34)) | P34: =IF(E34<30,"<30",IF(E34<40,"30-39","40+")) -> <30
A35: E1027 | B35: Sales | C35: Sales Executive | D35: Male | E35: 31 | F35: 43401 | G35: 45716 | H35: Left | I35: 44100 | J35: 2 | K35: 3 | L35: No | M35: Higher Studies | N35: =ROUND((IF(G35="",Analysis!$B$2,G35)-F35)/365.25,1) -> 6.3 | O35: =IF(G35="","",YEAR(G35)) -> 2025 | P35: =IF(E35<30,"<30",IF(E35<40,"30-39","40+")) -> 30-39
A36: E1208 | B36: Customer Support | C36: Team Lead | D36: Male | E36: 28 | F36: 45249 | H36: Active | I36: 44400 | J36: 2 | K36: 3 | L36: Yes | N36: =ROUND((IF(G36="",Analysis!$B$2,G36)-F36)/365.25,1) -> 2.9 | O36: =IF(G36="","",YEAR(G36)) | P36: =IF(E36<30,"<30",IF(E36<40,"30-39","40+")) -> <30
A37: E1476 | B37: Operations | C37: Operations Associate | D37: Female | E37: 34 | F37: 43254 | H37: Active | I37: 46900 | J37: 2 | K37: 4 | L37: No | N37: =ROUND((IF(G37="",Analysis!$B$2,G37)-F37)/365.25,1) -> 8.4 | O37: =IF(G37="","",YEAR(G37)) | P37: =IF(E37<30,"<30",IF(E37<40,"30-39","40+")) -> 30-39
A38: E1077 | B38: Sales | C38: Sales Executive | D38: Male | E38: 34 | F38: 44963 | H38: Active | I38: 48600 | J38: 2 | K38: 3 | L38: Yes | N38: =ROUND((IF(G38="",Analysis!$B$2,G38)-F38)/365.25,1) -> 3.7 | O38: =IF(G38="","",YEAR(G38)) | P38: =IF(E38<30,"<30",IF(E38<40,"30-39","40+")) -> 30-39
A39: E1061 | B39: Sales | C39: Sales Executive | D39: Male | E39: 31 | F39: 45377 | H39: Active | I39: 49100 | J39: 2 | K39: 5 | L39: Yes | N39: =ROUND((IF(G39="",Analysis!$B$2,G39)-F39)/365.25,1) -> 2.6 | O39: =IF(G39="","",YEAR(G39)) | P39: =IF(E39<30,"<30",IF(E39<40,"30-39","40+")) -> 30-39
A40: E1453 | B40: Operations | C40: Supervisor | D40: Female | E40: 33 | F40: 43429 | H40: Active | I40: 49300 | J40: 2 | K40: 5 | L40: No | N40: =ROUND((IF(G40="",Analysis!$B$2,G40)-F40)/365.25,1) -> 7.9 | O40: =IF(G40="","",YEAR(G40)) | P40: =IF(E40<30,"<30",IF(E40<40,"30-39","40+")) -> 30-39
...
